Workbook

Sheet README
A1: Please fill out the yellow highlighted areas in this document!
A2: You can leave the grey highlighted areas blank.
A3: If you have any questions, please contact your data management team.
A4: If you are the data management team and you have questions, please contact Katherine "Katie" Herrmann (katherine_herrmann@nps.gov).

Sheet attributes
A1: ATTRIBUTE METADATA
C2: Describe what this column contains in one plain-language sentence. • Start with a noun, not "This column is..." • Don't repeat the column name or include units or date formats (those have their own columns) • Spell out abbreviations and acronyms • For categorical fields, describe the variable only; codes are defined separately | D2: DO NOT EDIT CLASS | E2: Type the first few letters then pick from dropdown. • Full list shown in "unit_dictionary" tab. • For count, use "number". • If unit does not already exist, add it to the "custom units" tab first | F2: Y Year, M Month, D Day, h Hour, m Minute, s Second Examples: • YYYY-MM-DD for 2025-10-25 • hh:mm:ss for 11:25:42 AM | G2: The code(s) that describe missing values in the data. If the column contains NA, write NA. If the column is empty or contains "", write blank. For fields where missing values are not applicable or data should always be present, leave the field empty. | H2: If there is a blank or missing value in this column, what would that mean? For fields where missing values are not applicable or data should always be present, leave the field empty. Examples: • No data to collect/not present • We could not gather data at this point • Instrument error • Data missing

Sheet custom_units
A1: CUSTOM UNITS | B1: Description:
A2: ONLY FILL THIS OUT IF YOU NEED IT FOR THE ATTRIBUTES TABLE | B2: Units that are not already on the unit_directory tab. If you need to make a custom unit, find something similar on the unit_directory tab to use as a guideline.
A3: EXAMPLE:
A4: id | B4: unitType | C4: parentSI | D4: multiplierToSI | E4: description
A5: Ounces | B5: volume | C5: liter | D5: 0.02957353 | E5: US Fluid Ounce, a unit of volume equal to roughly 0.0295735 Liters
A7: ENTER CUSTOM UNITS BELOW:
A8: id | B8: unitType | C8: parentSI | D8: multiplierToSI | E8: description

Sheet unit_dictionary
A1: id | B1: name | C1: unitType | D1: udunitsSynonym | E1: description | F1: abbreviation | G1: multiplierToSI | H1: deprecatedInFavorOf | I1: parentSI | J1: constantToSI
A2: dimensionless | B2: dimensionless | C2: dimensionless | E2: a designation asserting the absence of an associated unit | F2: NA | G2: NA | H2: NA | I2: NA | J2: NA
A3: second | B3: second | C3: time | D3: second | E3: SI unit of time | F3: sec | G3: 1 | H3: NA | I3: NA | J3: NA
A4: meter | B4: meter | C4: length | D4: meter | E4: SI unit of length | F4: m | G4: 1 | H4: NA | I4: NA | J4: NA
A5: kilogram | B5: kilogram | C5: mass | D5: kilogram | E5: SI unit of mass | F5: kg | G5: 1 | H5: NA | I5: NA | J5: NA
A6: kelvin | B6: kelvin | C6: temperature | D6: kelvin | E6: SI unit of temperature | F6: K | G6: 1 | H6: NA | I6: NA | J6: NA
A7: coulomb | B7: coulomb | C7: charge | D7: coulomb | E7: SI unit of charge | F7: C | G7: 1 | H7: NA | I7: NA | J7: NA
A8: ampere | B8: ampere | C8: current | D8: ampere | E8: SI unit of electrical current | F8: A | G8: 1 | H8: NA | I8: NA | J8: NA
A9: mole | B9: mole | C9: amount | D9: mole | E9: SI unit of substance amount | F9: mol | G9: 1 | H9: NA | I9: NA | J9: NA
A10: candela | B10: candela | C10: luminosity | D10: candela | E10: SI base unit of luminous intensity (luminous power per unti solid angle emitted_x000D_ by a point light source in a particular direction) | F10: cd | G10: 1 | H10: NA | I10: NA | J10: NA
A11: number | B11: number | C11: dimensionless | D11: count | E11: a quantity or amount | F11: NA | G11: NA | H11: NA | I11: NA | J11: NA
A12: cubicMeter | B12: cubicMeter | C12: volume | D12: meter^3 | E12: cubic meter | F12: mÂ³ | G12: 1 | H12: meterCubed | I12: NA | J12: NA
A13: nominalMinute | B13: nominalMinute | C13: time | D13: minute | E13: one minute of time excluding leap seconds, 60 seconds | F13: NA | G13: 60 | H13: NA | I13: second | J13: NA
A14: nominalHour | B14: nominalHour | C14: time | D14: hour | E14: one hour excluding leap seconds, 3600 seconds | F14: NA | G14: 3600 | H14: NA | I14: second | J14: NA
A15: nominalDay | B15: nominalDay | C15: time | D15: day | E15: one day excluding leap seconds, 86400 seconds | F15: NA | G15: 86400 | H15: NA | I15: second | J15: NA
A16: nominalWeek | B16: nominalWeek | C16: time | D16: week | E16: one day excluding leap seconds, 604800 seconds | F16: NA | G16: 604800 | H16: NA | I16: second | J16: NA
A17: nominalYear | B17: nominalYear | C17: time | D17: common_year | E17: one year excluding leap seconds and leap days, 31536000 seconds | F17: NA | G17: 31536000 | H17: NA | I17: second | J17: NA
A18: nominalLeapYear | B18: nominalLeapYear | C18: time | D18: leap_year | E18: one 366 day year excluding leap seconds, 31622400 seconds | F18: NA | G18: 31622400 | H18: NA | I18: second | J18: NA
A19: nanogram | B19: nanogram | C19: mass | D19: nanogram | E19: 0.000000000001 kg | F19: ng | G19: 1e-12 | H19: NA | I19: kilogram | J19: NA
A20: microgram | B20: microgram | C20: mass | D20: microgram | E20: 0.000000001 kg | F20: Î¼g | G20: 1e-09 | H20: NA | I20: kilogram | J20: NA
A21: milligram | B21: milligram | C21: mass | D21: milligram | E21: 0.000001 kg | F21: mg | G21: 1e-06 | H21: NA | I21: kilogram | J21: NA
A22: centigram | B22: centigram | C22: mass | D22: centigram | E22: 0.00001 kg | F22: cg | G22: 1e-05 | H22: NA | I22: kilogram | J22: NA
A23: decigram | B23: decigram | C23: mass | D23: decigram | E23: 0.0001 kg | F23: dg | G23: 0.0001 | H23: NA | I23: kilogram | J23: NA
... A30: ton | B30: ton | C30: NA | D30: short_ton | E30: standard US (short) ton = 2000 lbs | F30: ton | G30: 907.1999 | H30: NA | I30: kilogram | J30: NA
A31: celsius | B31: celsius | C31: NA | D31: celsius | E31: A common unit of temperature | F31: C | G31: 1 | H31: NA | I31: kelvin | J31: 273.18
A32: fahrenheit | B32: fahrenheit | C32: NA | D32: fahrenheit | E32: unit for temperature on the scale in which water freezes at 32 and boils _x000D_ at 212 under standard conditions. | F32: F | G32: 0.556 | H32: NA | I32: kelvin | J32: 255.402
A33: nanometer | B33: nanometer | C33: NA | D33: nanometer | E33: .000000001 meters | F33: nm | G33: 1e-09 | H33: NA | I33: meter | J33: NA
A34: micrometer | B34: micrometer | C34: NA | D34: micrometer | E34: .000001 meters | F34: Î¼m | G34: 1e-06 | H34: NA | I34: meter | J34: NA
A35: micron | B35: micron | C35: NA | D35: micrometer | E35: .000001 meters | F35: Î¼ | G35: 1e-06 | H35: micrometer | I35: meter | J35: NA
A36: millimeter | B36: millimeter | C36: NA | D36: millimeter | E36: .001 meters | F36: mm | G36: 0.001 | H36: NA | I36: meter | J36: NA
A37: centimeter | B37: centimeter | C37: NA | D37: centimeter | E37: .01 meters | F37: cm | G37: 0.01 | H37: NA | I37: meter | J37: NA
A38: decimeter | B38: decimeter | C38: NA | D38: decimeter | E38: .1 meters | F38: dm | G38: 0.1 | H38: NA | I38: meter | J38: NA
A39: dekameter | B39: dekameter | C39: NA | D39: dekameter | E39: 10 meters | F39: dam | G39: 10 | H39: NA | I39: meter | J39: NA
A40: hectometer | B40: hectometer | C40: NA | D40: hectometer | E40: 100 meters | F40: hm | G40: 100 | H40: NA | I40: meter | J40: NA
A41: kilometer | B41: kilometer | C41: NA | D41: kilometer | E41: 1000 meters | F41: km | G41: 1000 | H41: NA | I41: meter | J41: NA
A42: megameter | B42: megameter | C42: NA | D42: megameter | E42: 1000000 meters | F42: Mm | G42: 1000000 | H42: NA | I42: meter | J42: NA
A43: angstrom | B43: angstrom | C43: NA | D43: angstrom | E43: 1/10000000000 meter | F43: Ã… | G43: 1e-10 | H43: NA | I43: meter | J43: NA
A44: inch | B44: inch | C44: NA | D44: international_inch | E44: unit of length in the (British) imperial and United States systems _x000D_ usually understood as 1/12 f a foot. | F44: in | G44: 0.0254 | H44: NA | I44: meter | J44: NA
... A46: foot | B46: foot | C46: NA | D46: international_foot | E46: 12 inches | F46: ft | G46: 0.3048 | H46: NA | I46: meter | J46: NA
A47: Foot_Gold_Coast | B47: Foot_Gold_Coast | C47: NA | E47: 12 inches | F47: gcft | G47: 0.3047997 | H47: NA | I47: meter | J47: NA
...

Sheet catagorical_value_definitions
A1: CATAGORICAL VALUE DEFINITIONS

Sheet abstract
A1: Description: | B1: ENTER ABSTRACT BELOW:
A2: Describes the salient features of a dataset in a concise summary much like an abstract does in a journal article. It should cover what the data are and why they were created. A good rule of thumb is that an abstract should be about 250 words or less. The abstract will become a publicly-facing piece of text featured on the DataStore reference page as well as sent on to DataCite, data.gov, and Google’s Dataset Search. A thoughtful and well-planned abstract may be useable not only for the data package but also for the Data Release Report (DRR). If you write your abstract in a word processor (such as MS Word) and paste it in to the abstract.txt template file, please pass it through a text editor (such as Notepad) to make sure it is UTF-8 encoded and does not have special characters, including line breaks such as <br>.
A3: If the abstract is too short it will look like this
A4: If the abstract is the right length it will look like this
A5: If the abstract is too long it will look like this
A6: If the abstract is especially too long it will look like this
A7: EXAMPLE:
A8: Vegetation communities serve as the foundation of habitat for many species, function as a carbon sink, produce oxygen, cycle nutrients and energy, improve water quality, and moderate flooding/erosion. Given the widespread anthropogenic influences in Southeast Coast Network parks and the importance of vegetation communities, quantifying trends in species diversity and forest regeneration is vital to understanding ecological processes and identifying stressors and their impacts. Evaluating trends in vegetation and environmental attributes provides measures for assessing the ecological integrity and sustainability of park’s terrestrial vegetation and identifies potential management activities on our park lands. The National Park Service Omnibus Management Act of 1998 and other reinforcing policies and regulations require park managers to establish baseline information and to provide information on the long-term trends in the condition of National Park System resources (Title II, Sec. 204). The data summarized herein is a tool to assist managers in fulfilling this mandate.

Sheet methods
A1: Description: | B1: ENTER METHODS BELOW:
A2: Describes the data creation methods. Includes enough detail for future users to correctly use the data. Lists instrument descriptions, protocols, etc. Methods sections can include citations. It may be appropriate to cite the Protocol, datasets that were ingested to generate the data package, software (e.g. R), packages (e.g. dplyr, ggplot2) or custom scripts.
A3: Example:
A4: The Southeast Coast Network collects vegetation monitoring data within long-term, monumented, geo-referenced plots. Each plot consists of a 20 x 20 meter bounded square divided into four 10 x 10 meter modules; three 25 meter transects that traverse the bounded square; and three soil sample frames located adjacent to the bounded square. Vascular species presence is recorded across three spatial scales within each module—1 square meter, 10 square meter, and 100 square meter—and cover is recorded at the module scale for each species either present in or overhanging the module. Woody stems include trees, saplings and seedlings. Diameters and health of all trees are recorded within the plot, while counts of saplings and seedlings are recorded within quadrats. Other data collected include canopy height and cover, disturbance observations, downed woody debris, and landform. Botanical nomenclature at present conforms to Weakley 2020 Flora of the Southeastern U.S. A full description of all data collection methods can be found on NPS DataStore: https://irma.nps.gov/DataStore/Reference/Profile/2263392

Sheet keywords
A1: Description:
A2: Describes the data in a small set of terms. Keywords facilitate search and discovery on scientific terms, as well as names of research groups, field stations, and other organizations. Using a controlled vocabulary or thesaurus vastly improves discovery. We recommend using the LTER Controlled Vocabulary when possible.
A3: Example: | B3: ENTER KEYWORDS BELOW:
A4: keyword | B4: keyword | C4: keywordThesaurus
A5: Palo Verde National Park | C5: =IFERROR(VLOOKUP(B5, suggested_keywords!A:B, 2, FALSE), "")
A6: pesticides | C6: =IFERROR(VLOOKUP(B6, suggested_keywords!A:B, 2, FALSE), "")
A7: environmental risk | C7: =IFERROR(VLOOKUP(B7, suggested_keywords!A:B, 2, FALSE), "")
A8: tropical wetland | C8: =IFERROR(VLOOKUP(B8, suggested_keywords!A:B, 2, FALSE), "")
A9: aquatic macroinvertebrate | C9: =IFERROR(VLOOKUP(B9, suggested_keywords!A:B, 2, FALSE), "")
C10: =IFERROR(VLOOKUP(B10, suggested_keywords!A:B, 2, FALSE), "")
C11: =IFERROR(VLOOKUP(B11, suggested_keywords!A:B, 2, FALSE), "")
C12: =IFERROR(VLOOKUP(B12, suggested_keywords!A:B, 2, FALSE), "")
C13: =IFERROR(VLOOKUP(B13, suggested_keywords!A:B, 2, FALSE), "")
C14: =IFERROR(VLOOKUP(B14, suggested_keywords!A:B, 2, FALSE), "")
C15: =IFERROR(VLOOKUP(B15, suggested_keywords!A:B, 2, FALSE), "")
C16: =IFERROR(VLOOKUP(B16, suggested_keywords!A:B, 2, FALSE), "")
C17: =IFERROR(VLOOKUP(B17, suggested_keywords!A:B, 2, FALSE), "")
C18: =IFERROR(VLOOKUP(B18, suggested_keywords!A:B, 2, FALSE), "")
C19: =IFERROR(VLOOKUP(B19, suggested_keywords!A:B, 2, FALSE), "")
C20: =IFERROR(VLOOKUP(B20, suggested_keywords!A:B, 2, FALSE), "")
C21: =IFERROR(VLOOKUP(B21, suggested_keywords!A:B, 2, FALSE), "")
... C77: =IFERROR(VLOOKUP(B77, suggested_keywords!A:B, 2, FALSE), "")

Sheet suggested_keywords
A1: keyword | B1: keywordThesaurus
A2: Air and Climate | Air Quality | Air Contaminants | B2: Ecological Framework
A3: Air and Climate | Air Quality | Ozone | B3: Ecological Framework
A4: Air and Climate | Air Quality | Visibility and Particulate Matter | B4: Ecological Framework
A5: Air and Climate | Air Quality | Wet and Dry Deposition | B5: Ecological Framework
A6: Air and Climate | Weather and Climate | Weather and Climate | B6: Ecological Framework
A7: Biological Integrity | At-risk Biota | T&E Species and Communities | B7: Ecological Framework
A8: Biological Integrity | Focal Species or Communities | Amphibians and Reptiles | B8: Ecological Framework
A9: Biological Integrity | Focal Species or Communities | Birds | B9: Ecological Framework
A10: Biological Integrity | Focal Species or Communities | Cave Communities | B10: Ecological Framework
A11: Biological Integrity | Focal Species or Communities | Desert Communities | B11: Ecological Framework
A12: Biological Integrity | Focal Species or Communities | Estuarine Communities | B12: Ecological Framework
... A67: Water | Water Quality | Water Chemistry | B67: Ecological Framework

Sheet personnel
A1: PERSONNEL METADATA
A2: Examples:
A3: givenName | B3: middleInitial | C3: surName | D3: organizationName | E3: electronicMailAddress | F3: userId | G3: role | H3: projectTitle | I3: fundingAgency | J3: fundingNumber
A4: Doe | B4: B | C4: Jane | D4: South Florida/Caribbean Network | E4: jane_doe@fake_email.com | G4: Contact | H4: South Florida/Caribbean Network Early Detection Protocol for Exotic Plants
A5: Doe | B5: B | C5: Jane | D5: South Florida/Caribbean Network | E5: jane_doe@fake_email.com | G5: Creator | H5: South Florida/Caribbean Network Early Detection Protocol for Exotic Plants
A6: Katherine | B6: R | C6: Herrmann | D6: South Florida/Caribbean Network | E6: Katherine_Herrmann@nps.gov | F6: 0009-0004-5746-8322 | G6: Creator | H6: South Florida/Caribbean Network Early Detection Protocol for Exotic Plants
A7: River | B7: T | C7: Otter | D7: Otter University | E7: river_t_otter@otteru.edu | G7: Creator | H7: South Florida/Caribbean Network Early Detection Protocol for Exotic Plants
A8: Canada | C8: Goose | D8: Goose Inc. | E8: duck_duck@goose.net | G8: Creator | H8: South Florida/Caribbean Network Early Detection Protocol for Exotic Plants
A12: ENTER PERSONNEL BELOW: | F12: userId is ORCID | G12: REQUIRES at least one Creator and one Contact If Creator and Contact are the same, you will need to enter their information twice, once for each role | I12: Probably not needed | J12: Probably not needed
A13: givenName | B13: middleInitial | C13: surName | D13: organizationName | E13: electronicMailAddress | F13: userId | G13: role | H13: projectTitle | I13: fundingAgency | J13: fundingNumber
A14: Fill this row out! | G14: Creator
A15: Fill this row out! | G15: Contact

Sheet table_info
A1: Data Names and Descriptions
B2: Data names are the names of the tables (more than just the csv title). | C2: Data descriptions are more in depth descriptions of what the table holds. Aim for around 15 words. | D2: If you go over 25 words the description will look like this
A3: File Name | B3: Data Name | C3: Data Description

Sheet additional_info
A1: Description: | B1: ENTER ADDITIONAL INFO BELOW:
A2: Ancillary info not captured by any of the other templates. If you write your additional info in a word processor (such as MS Word) and paste it in to the abstract.txt template file, please pass it through a text editor (such as Notepad) to make sure it is UTF-8 encoded and does not have special characters, including line breaks such as <br>.
A3: Example:
